INFO 2022-03-02 18:52:22,583 autoreload 643 Watching for file changes with StatReloader
INFO 2022-03-02 18:52:23,472 basehttp 179 "GET /admin/ HTTP/1.1" 200 23635
INFO 2022-03-02 18:52:23,980 basehttp 179 "GET /admin/user/blog/ HTTP/1.1" 200 26827
INFO 2022-03-02 18:52:24,104 basehttp 179 "GET /admin/jsi18n/ HTTP/1.1" 200 8398
INFO 2022-03-02 18:52:25,148 basehttp 179 "GET /admin/user/blog/7/change/ HTTP/1.1" 200 26118
INFO 2022-03-02 18:52:25,220 basehttp 179 "GET /admin/jsi18n/ HTTP/1.1" 200 8398
INFO 2022-03-02 18:52:27,756 basehttp 179 "POST /admin/user/blog/7/change/ HTTP/1.1" 302 0
INFO 2022-03-02 18:52:27,843 basehttp 179 "GET /admin/user/blog/ HTTP/1.1" 200 26990
INFO 2022-03-02 18:52:27,904 basehttp 179 "GET /admin/jsi18n/ HTTP/1.1" 200 8398
INFO 2022-03-02 18:55:50,303 autoreload 257 D:\python\newblog\dblog\dblog\settings.py changed, reloading.
ERROR 2022-03-07 09:45:35,234 log 225 Internal Server Error: /user/viewnum/
Traceback (most recent call last):
  File "/usr/local/lib/python3.8/dist-packages/django/core/handlers/exception.py", line 47, in inner
    response = get_response(request)
  File "/usr/local/lib/python3.8/dist-packages/django/core/handlers/base.py", line 181, in _get_response
    response = wrapped_callback(request, *callback_args, **callback_kwargs)
  File "/usr/local/lib/python3.8/dist-packages/django/views/decorators/csrf.py", line 54, in wrapped_view
    return view_func(*args, **kwargs)
  File "/usr/local/lib/python3.8/dist-packages/django/views/generic/base.py", line 69, in view
    return self.dispatch(request, *args, **kwargs)
  File "/usr/local/lib/python3.8/dist-packages/rest_framework/views.py", line 509, in dispatch
    response = self.handle_exception(exc)
  File "/usr/local/lib/python3.8/dist-packages/rest_framework/views.py", line 469, in handle_exception
    self.raise_uncaught_exception(exc)
  File "/usr/local/lib/python3.8/dist-packages/rest_framework/views.py", line 480, in raise_uncaught_exception
    raise exc
  File "/usr/local/lib/python3.8/dist-packages/rest_framework/views.py", line 506, in dispatch
    response = handler(request, *args, **kwargs)
  File "/home/django_blog/user/views.py", line 81, in get
    visit_obj.today_num += 1
AttributeError: 'NoneType' object has no attribute 'today_num'
ERROR 2022-03-07 09:45:35,244 basehttp 179 "GET /user/viewnum/ HTTP/1.1" 500 145
ERROR 2022-03-07 13:01:04,656 log 225 Internal Server Error: /user/viewnum/
Traceback (most recent call last):
  File "/usr/local/lib/python3.8/dist-packages/django/core/handlers/exception.py", line 47, in inner
    response = get_response(request)
  File "/usr/local/lib/python3.8/dist-packages/django/core/handlers/base.py", line 181, in _get_response
    response = wrapped_callback(request, *callback_args, **callback_kwargs)
  File "/usr/local/lib/python3.8/dist-packages/django/views/decorators/csrf.py", line 54, in wrapped_view
    return view_func(*args, **kwargs)
  File "/usr/local/lib/python3.8/dist-packages/django/views/generic/base.py", line 69, in view
    return self.dispatch(request, *args, **kwargs)
  File "/usr/local/lib/python3.8/dist-packages/rest_framework/views.py", line 509, in dispatch
    response = self.handle_exception(exc)
  File "/usr/local/lib/python3.8/dist-packages/rest_framework/views.py", line 469, in handle_exception
    self.raise_uncaught_exception(exc)
  File "/usr/local/lib/python3.8/dist-packages/rest_framework/views.py", line 480, in raise_uncaught_exception
    raise exc
  File "/usr/local/lib/python3.8/dist-packages/rest_framework/views.py", line 506, in dispatch
    response = handler(request, *args, **kwargs)
  File "/home/django_blog/user/views.py", line 81, in get
    visit_obj.today_num += 1
AttributeError: 'NoneType' object has no attribute 'today_num'
ERROR 2022-03-07 13:01:04,674 basehttp 179 "GET /user/viewnum/ HTTP/1.1" 500 145
ERROR 2022-03-07 13:38:03,086 log 225 Internal Server Error: /user/viewnum/
Traceback (most recent call last):
  File "/usr/local/lib/python3.8/dist-packages/django/core/handlers/exception.py", line 47, in inner
    response = get_response(request)
  File "/usr/local/lib/python3.8/dist-packages/django/core/handlers/base.py", line 181, in _get_response
    response = wrapped_callback(request, *callback_args, **callback_kwargs)
  File "/usr/local/lib/python3.8/dist-packages/django/views/decorators/csrf.py", line 54, in wrapped_view
    return view_func(*args, **kwargs)
  File "/usr/local/lib/python3.8/dist-packages/django/views/generic/base.py", line 69, in view
    return self.dispatch(request, *args, **kwargs)
  File "/usr/local/lib/python3.8/dist-packages/rest_framework/views.py", line 509, in dispatch
    response = self.handle_exception(exc)
  File "/usr/local/lib/python3.8/dist-packages/rest_framework/views.py", line 469, in handle_exception
    self.raise_uncaught_exception(exc)
  File "/usr/local/lib/python3.8/dist-packages/rest_framework/views.py", line 480, in raise_uncaught_exception
    raise exc
  File "/usr/local/lib/python3.8/dist-packages/rest_framework/views.py", line 506, in dispatch
    response = handler(request, *args, **kwargs)
  File "./user/views.py", line 81, in get
    visit_obj.today_num += 1
AttributeError: 'NoneType' object has no attribute 'today_num'
ERROR 2022-03-07 13:40:54,437 log 225 Internal Server Error: /user/viewnum/
Traceback (most recent call last):
  File "/usr/local/lib/python3.8/dist-packages/django/core/handlers/exception.py", line 47, in inner
    response = get_response(request)
  File "/usr/local/lib/python3.8/dist-packages/django/core/handlers/base.py", line 181, in _get_response
    response = wrapped_callback(request, *callback_args, **callback_kwargs)
  File "/usr/local/lib/python3.8/dist-packages/django/views/decorators/csrf.py", line 54, in wrapped_view
    return view_func(*args, **kwargs)
  File "/usr/local/lib/python3.8/dist-packages/django/views/generic/base.py", line 69, in view
    return self.dispatch(request, *args, **kwargs)
  File "/usr/local/lib/python3.8/dist-packages/rest_framework/views.py", line 509, in dispatch
    response = self.handle_exception(exc)
  File "/usr/local/lib/python3.8/dist-packages/rest_framework/views.py", line 469, in handle_exception
    self.raise_uncaught_exception(exc)
  File "/usr/local/lib/python3.8/dist-packages/rest_framework/views.py", line 480, in raise_uncaught_exception
    raise exc
  File "/usr/local/lib/python3.8/dist-packages/rest_framework/views.py", line 506, in dispatch
    response = handler(request, *args, **kwargs)
  File "./user/views.py", line 81, in get
    visit_obj.today_num += 1
AttributeError: 'NoneType' object has no attribute 'today_num'
ERROR 2022-03-07 13:50:50,909 log 225 Internal Server Error: /user/viewnum/
Traceback (most recent call last):
  File "/usr/local/lib/python3.8/dist-packages/django/core/handlers/exception.py", line 47, in inner
    response = get_response(request)
  File "/usr/local/lib/python3.8/dist-packages/django/core/handlers/base.py", line 181, in _get_response
    response = wrapped_callback(request, *callback_args, **callback_kwargs)
  File "/usr/local/lib/python3.8/dist-packages/django/views/decorators/csrf.py", line 54, in wrapped_view
    return view_func(*args, **kwargs)
  File "/usr/local/lib/python3.8/dist-packages/django/views/generic/base.py", line 69, in view
    return self.dispatch(request, *args, **kwargs)
  File "/usr/local/lib/python3.8/dist-packages/rest_framework/views.py", line 509, in dispatch
    response = self.handle_exception(exc)
  File "/usr/local/lib/python3.8/dist-packages/rest_framework/views.py", line 469, in handle_exception
    self.raise_uncaught_exception(exc)
  File "/usr/local/lib/python3.8/dist-packages/rest_framework/views.py", line 480, in raise_uncaught_exception
    raise exc
  File "/usr/local/lib/python3.8/dist-packages/rest_framework/views.py", line 506, in dispatch
    response = handler(request, *args, **kwargs)
  File "./user/views.py", line 81, in get
    visit_obj.today_num += 1
AttributeError: 'NoneType' object has no attribute 'today_num'
